Workbook

Sheet СВОД
A1: Б.# | B1: Вид объекта: | C1: Разделы ЦИМ: | D1: Класс IFC: | E1: Элемент: | F1: Код МССК: | G1: Группа | H1: № | I1: Набор атрибутов | J1: Наименование параметра | K1: Имя параметра IFC | L1: Тип данных | M1: Ед.изм. | N1: Пример | O1: Изм.
A2: Б.0 | B2: Непроизводственного назначения | C2: Объемно-планировочные и архитектурные решения | D2: IfcBuilding | E2: Объект | G2: Сведения о проекте | H2: 1 | I2: RusSet_Project | J2: Наименование проекта | K2: RUS_ProjectName | L2: Текстовый | M2: - | N2: Жилой дом | O2: +
A3: Б.0 | B3: Непроизводственного назначения | C3: Объемно-планировочные и архитектурные решения | D3: IfcBuilding | E3: Объект | G3: Сведения о проекте | H3: 2 | I3: RusSet_Project | J3: Адрес | K3: RUS_BuildingAddress | L3: Текстовый | M3: - | N3: г. Москва, Проспект Мира | O3: +
A4: Б.0 | B4: Непроизводственного назначения | C4: Объемно-планировочные и архитектурные решения | D4: IfcBuilding | E4: Объект | G4: Материалы АГР | H4: 3 | I4: RusSet_AGR | J4: Функциональное назначение объекта | K4: RUS_FNO | L4: Текстовый | M4: - | N4: Жилое здание/Нежилое здание | O4: +
A5: Б.1 | B5: Непроизводственного назначения | C5: Объемно-планировочные и архитектурные решения | D5: IfcBuildingElementProxy | E5: Вспомогательное 3D-тело | F5: ЭЛ 30 30 10, ЭЛ 30 30 20 | G5: Общие данные | H5: 1 | I5: RusSet_Common | J5: Код элемента МССК | K5: RUS_MSSK_Element_Code | L5: Текстовый | M5: - | N5: ЭЛ 30 30 | O5: +
A6: Б.1 | B6: Непроизводственного назначения | C6: Объемно-планировочные и архитектурные решения | D6: IfcBuildingElementProxy | E6: Вспомогательное 3D-тело | F6: ЭЛ 30 30 10, ЭЛ 30 30 20 | G6: Общие данные | H6: 2 | I6: RusSet_Common | J6: Наименование | K6: RUS_Name | L6: Текстовый | M6: - | N6: Объем подземной части здания | O6: +
A7: Б.1 | B7: Непроизводственного назначения | C7: Объемно-планировочные и архитектурные решения | D7: IfcBuildingElementProxy | E7: Вспомогательное 3D-тело | F7: ЭЛ 30 30 10, ЭЛ 30 30 20 | G7: Общие данные | H7: 3 | I7: RusSet_Common | J7: Наименование элемента МССК | K7: RUS_MSSK_Element_Name | L7: Текстовый | M7: - | N7: Подземная часть здания | O7: +
A8: Б.1 | B8: Непроизводственного назначения | C8: Объемно-планировочные и архитектурные решения | D8: IfcBuildingElementProxy | E8: Вспомогательное 3D-тело | F8: ЭЛ 30 30 10, ЭЛ 30 30 20 | G8: Количественные параметры | H8: 4 | I8: RusSet_Quantities | J8: Объем | K8: RUS_Volume | L8: Вещественный | M8: куб.м. | N8: 30 | O8: отменён
A9: Б.1 | B9: Непроизводственного назначения | C9: Объемно-планировочные и архитектурные решения | D9: IfcBuildingElementProxy | E9: Вспомогательное 3D-тело | F9: ЭЛ 30 30 10, ЭЛ 30 30 20 | G9: Количественные параметры | H9: 5 | I9: RusSet_Quantities | J9: Высота | K9: RUS_Height | L9: Вещественный | M9: мм | N9: 300 | O9: отменён
A10: Б.1 | B10: Непроизводственного назначения | C10: Объемно-планировочные и архитектурные решения | D10: IfcBuildingElementProxy | E10: Вспомогательное 3D-тело | F10: ЭЛ 30 30 10, ЭЛ 30 30 20 | G10: Количественные параметры | H10: 6 | I10: RusSet_Quantities | J10: Ширина | K10: RUS_Width | L10: Вещественный | M10: мм | N10: 300 | O10: отменён
A11: Б.1 | B11: Непроизводственного назначения | C11: Объемно-планировочные и архитектурные решения | D11: IfcBuildingElementProxy | E11: Вспомогательное 3D-тело | F11: ЭЛ 30 30 10, ЭЛ 30 30 20 | G11: Количественные параметры | H11: 7 | I11: RusSet_Quantities | J11: Длина | K11: RUS_Length | L11: Вещественный | M11: мм | N11: 12.5 | O11: отменён
A12: Б.1 | B12: Непроизводственного назначения | C12: Объемно-планировочные и архитектурные решения | D12: IfcBuildingElementProxy | E12: Вспомогательное 3D-тело | F12: ЭЛ 30 30 10, ЭЛ 30 30 20 | G12: Местоположение | H12: 8 | I12: RusSet_Location | J12: Номер объекта (корпуса) | K12: RUS_Object | L12: Текстовый | M12: - | N12: К01 | O12: +
A13: Б.1 | B13: Непроизводственного назначения | C13: Объемно-планировочные и архитектурные решения | D13: IfcBuildingElementProxy | E13: Вспомогательное 3D-тело | F13: ЭЛ 30 30 10, ЭЛ 30 30 20 | G13: Местоположение | H13: 9 | I13: RusSet_Location | J13: Номер подобъекта (секции) | K13: RUS_Object_Sub | L13: Текстовый | M13: - | N13: С01 | O13: +
A14: Б.2 | B14: Непроизводственного назначения | C14: Объемно-планировочные и архитектурные решения | D14: IfcSpace | E14: Помещение | F14: ПЗ 30, ПЗ 30 10, ПЗ 30 20, ПЗ 30 30, ПЗ 31 01, ПЗ 31 02, ПЗ 31 03, ПЗ 31 04, ПЗ 31 05, ПЗ 31 06, ПЗ 31 07, ПЗ 31 08, ПЗ 31 09, ПЗ 31 10, ПЗ 31 12, ПЗ 31 13, ПЗ 31 14, ПЗ 31 15, ПЗ 31 16, ПЗ 31 17, ПЗ 32 10, ПЗ 32 12, ПЗ 32 13, ПЗ 32 14, ПЗ 32 15, ПЗ 32 16, ПЗ 33 10, ПЗ 33 12, ПЗ 33 13, ПЗ 33 14, ПЗ 33 15, ПЗ 33 16, ПЗ 33 17, ПЗ 33 18, ПЗ 33 19, ПЗ 33 20, ПЗ 33 21, ПЗ 33 22, ПЗ 33 23, ПЗ 33 24, ПЗ 33 25, ПЗ 33 26, ПЗ 33 27, ПЗ 33 28, ПЗ 33 29, ПЗ 33 30, ПЗ 33 31, ПЗ 33 32, ПЗ 33 33, ПЗ 34 10, ПЗ 34 12 | G14: Общие данные | H14: 1 | I14: RusSet_Common | J14: Код помещения и зоны МССК | K14: RUS_MSSK_SpaceAndZone_Code | L14: Текстовый | M14: - | N14: ПЗ 30 20 07 | O14: +
A15: Б.2 | B15: Непроизводственного назначения | C15: Объемно-планировочные и архитектурные решения | D15: IfcSpace | E15: Помещение | F15: ПЗ 30, ПЗ 30 10, ПЗ 30 20, ПЗ 30 30, ПЗ 31 01, ПЗ 31 02, ПЗ 31 03, ПЗ 31 04, ПЗ 31 05, ПЗ 31 06, ПЗ 31 07, ПЗ 31 08, ПЗ 31 09, ПЗ 31 10, ПЗ 31 12, ПЗ 31 13, ПЗ 31 14, ПЗ 31 15, ПЗ 31 16, ПЗ 31 17, ПЗ 32 10, ПЗ 32 12, ПЗ 32 13, ПЗ 32 14, ПЗ 32 15, ПЗ 32 16, ПЗ 33 10, ПЗ 33 12, ПЗ 33 13, ПЗ 33 14, ПЗ 33 15, ПЗ 33 16, ПЗ 33 17, ПЗ 33 18, ПЗ 33 19, ПЗ 33 20, ПЗ 33 21, ПЗ 33 22, ПЗ 33 23, ПЗ 33 24, ПЗ 33 25, ПЗ 33 26, ПЗ 33 27, ПЗ 33 28, ПЗ 33 29, ПЗ 33 30, ПЗ 33 31, ПЗ 33 32, ПЗ 33 33, ПЗ 34 10, ПЗ 34 12 | G15: Общие данные | H15: 2 | I15: RusSet_Common | J15: Наименование | K15: RUS_Name | L15: Текстовый | M15: - | N15: Кухня | O15: +
A16: Б.2 | B16: Непроизводственного назначения | C16: Объемно-планировочные и архитектурные решения | D16: IfcSpace | E16: Помещение | F16: ПЗ 30, ПЗ 30 10, ПЗ 30 20, ПЗ 30 30, ПЗ 31 01, ПЗ 31 02, ПЗ 31 03, ПЗ 31 04, ПЗ 31 05, ПЗ 31 06, ПЗ 31 07, ПЗ 31 08, ПЗ 31 09, ПЗ 31 10, ПЗ 31 12, ПЗ 31 13, ПЗ 31 14, ПЗ 31 15, ПЗ 31 16, ПЗ 31 17, ПЗ 32 10, ПЗ 32 12, ПЗ 32 13, ПЗ 32 14, ПЗ 32 15, ПЗ 32 16, ПЗ 33 10, ПЗ 33 12, ПЗ 33 13, ПЗ 33 14, ПЗ 33 15, ПЗ 33 16, ПЗ 33 17, ПЗ 33 18, ПЗ 33 19, ПЗ 33 20, ПЗ 33 21, ПЗ 33 22, ПЗ 33 23, ПЗ 33 24, ПЗ 33 25, ПЗ 33 26, ПЗ 33 27, ПЗ 33 28, ПЗ 33 29, ПЗ 33 30, ПЗ 33 31, ПЗ 33 32, ПЗ 33 33, ПЗ 34 10, ПЗ 34 12 | G16: Общие данные | H16: 3 | I16: RusSet_Common | J16: Наименование помещения и зоны МССК | K16: RUS_MSSK_SpaceAndZone_Name | L16: Текстовый | M16: - | N16: Кухня | O16: +
A17: Б.2 | B17: Непроизводственного назначения | C17: Объемно-планировочные и архитектурные решения | D17: IfcSpace | E17: Помещение | F17: ПЗ 30, ПЗ 30 10, ПЗ 30 20, ПЗ 30 30, ПЗ 31 01, ПЗ 31 02, ПЗ 31 03, ПЗ 31 04, ПЗ 31 05, ПЗ 31 06, ПЗ 31 07, ПЗ 31 08, ПЗ 31 09, ПЗ 31 10, ПЗ 31 12, ПЗ 31 13, ПЗ 31 14, ПЗ 31 15, ПЗ 31 16, ПЗ 31 17, ПЗ 32 10, ПЗ 32 12, ПЗ 32 13, ПЗ 32 14, ПЗ 32 15, ПЗ 32 16, ПЗ 33 10, ПЗ 33 12, ПЗ 33 13, ПЗ 33 14, ПЗ 33 15, ПЗ 33 16, ПЗ 33 17, ПЗ 33 18, ПЗ 33 19, ПЗ 33 20, ПЗ 33 21, ПЗ 33 22, ПЗ 33 23, ПЗ 33 24, ПЗ 33 25, ПЗ 33 26, ПЗ 33 27, ПЗ 33 28, ПЗ 33 29, ПЗ 33 30, ПЗ 33 31, ПЗ 33 32, ПЗ 33 33, ПЗ 34 10, ПЗ 34 12 | G17: Количественные параметры | H17: 4 | I17: RusSet_Quantities | J17: Высота | K17: RUS_Height | L17: Вещественный | M17: мм | N17: 3300 | O17: отменён
A18: Б.2 | B18: Непроизводственного назначения | C18: Объемно-планировочные и архитектурные решения | D18: IfcSpace | E18: Помещение | F18: ПЗ 30, ПЗ 30 10, ПЗ 30 20, ПЗ 30 30, ПЗ 31 01, ПЗ 31 02, ПЗ 31 03, ПЗ 31 04, ПЗ 31 05, ПЗ 31 06, ПЗ 31 07, ПЗ 31 08, ПЗ 31 09, ПЗ 31 10, ПЗ 31 12, ПЗ 31 13, ПЗ 31 14, ПЗ 31 15, ПЗ 31 16, ПЗ 31 17, ПЗ 32 10, ПЗ 32 12, ПЗ 32 13, ПЗ 32 14, ПЗ 32 15, ПЗ 32 16, ПЗ 33 10, ПЗ 33 12, ПЗ 33 13, ПЗ 33 14, ПЗ 33 15, ПЗ 33 16, ПЗ 33 17, ПЗ 33 18, ПЗ 33 19, ПЗ 33 20, ПЗ 33 21, ПЗ 33 22, ПЗ 33 23, ПЗ 33 24, ПЗ 33 25, ПЗ 33 26, ПЗ 33 27, ПЗ 33 28, ПЗ 33 29, ПЗ 33 30, ПЗ 33 31, ПЗ 33 32, ПЗ 33 33, ПЗ 34 10, ПЗ 34 12 | G18: Количественные параметры | H18: 5 | I18: RusSet_Quantities | J18: Площадь | K18: RUS_Area | L18: Вещественный | M18: кв.м. | N18: 40 | O18: +
A19: Б.2 | B19: Непроизводственного назначения | C19: Объемно-планировочные и архитектурные решения | D19: IfcSpace | E19: Помещение | F19: ПЗ 30, ПЗ 30 10, ПЗ 30 20, ПЗ 30 30, ПЗ 31 01, ПЗ 31 02, ПЗ 31 03, ПЗ 31 04, ПЗ 31 05, ПЗ 31 06, ПЗ 31 07, ПЗ 31 08, ПЗ 31 09, ПЗ 31 10, ПЗ 31 12, ПЗ 31 13, ПЗ 31 14, ПЗ 31 15, ПЗ 31 16, ПЗ 31 17, ПЗ 32 10, ПЗ 32 12, ПЗ 32 13, ПЗ 32 14, ПЗ 32 15, ПЗ 32 16, ПЗ 33 10, ПЗ 33 12, ПЗ 33 13, ПЗ 33 14, ПЗ 33 15, ПЗ 33 16, ПЗ 33 17, ПЗ 33 18, ПЗ 33 19, ПЗ 33 20, ПЗ 33 21, ПЗ 33 22, ПЗ 33 23, ПЗ 33 24, ПЗ 33 25, ПЗ 33 26, ПЗ 33 27, ПЗ 33 28, ПЗ 33 29, ПЗ 33 30, ПЗ 33 31, ПЗ 33 32, ПЗ 33 33, ПЗ 34 10, ПЗ 34 12 | G19: Количественные параметры | H19: 6 | I19: RusSet_Quantities | J19: Объем | K19: RUS_Volume | L19: Вещественный | M19: куб.м. | N19: 60 | O19: отменён
A20: Б.2 | B20: Непроизводственного назначения | C20: Объемно-планировочные и архитектурные решения | D20: IfcSpace | E20: Помещение | F20: ПЗ 30, ПЗ 30 10, ПЗ 30 20, ПЗ 30 30, ПЗ 31 01, ПЗ 31 02, ПЗ 31 03, ПЗ 31 04, ПЗ 31 05, ПЗ 31 06, ПЗ 31 07, ПЗ 31 08, ПЗ 31 09, ПЗ 31 10, ПЗ 31 12, ПЗ 31 13, ПЗ 31 14, ПЗ 31 15, ПЗ 31 16, ПЗ 31 17, ПЗ 32 10, ПЗ 32 12, ПЗ 32 13, ПЗ 32 14, ПЗ 32 15, ПЗ 32 16, ПЗ 33 10, ПЗ 33 12, ПЗ 33 13, ПЗ 33 14, ПЗ 33 15, ПЗ 33 16, ПЗ 33 17, ПЗ 33 18, ПЗ 33 19, ПЗ 33 20, ПЗ 33 21, ПЗ 33 22, ПЗ 33 23, ПЗ 33 24, ПЗ 33 25, ПЗ 33 26, ПЗ 33 27, ПЗ 33 28, ПЗ 33 29, ПЗ 33 30, ПЗ 33 31, ПЗ 33 32, ПЗ 33 33, ПЗ 34 10, ПЗ 34 12 | G20: Местоположение | H20: 7 | I20: RusSet_Location | J20: Номер объекта (корпуса) | K20: RUS_Object | L20: Текстовый | M20: - | N20: К01 | O20: +
A21: Б.2 | B21: Непроизводственного назначения | C21: Объемно-планировочные и архитектурные решения | D21: IfcSpace | E21: Помещение | F21: ПЗ 30, ПЗ 30 10, ПЗ 30 20, ПЗ 30 30, ПЗ 31 01, ПЗ 31 02, ПЗ 31 03, ПЗ 31 04, ПЗ 31 05, ПЗ 31 06, ПЗ 31 07, ПЗ 31 08, ПЗ 31 09, ПЗ 31 10, ПЗ 31 12, ПЗ 31 13, ПЗ 31 14, ПЗ 31 15, ПЗ 31 16, ПЗ 31 17, ПЗ 32 10, ПЗ 32 12, ПЗ 32 13, ПЗ 32 14, ПЗ 32 15, ПЗ 32 16, ПЗ 33 10, ПЗ 33 12, ПЗ 33 13, ПЗ 33 14, ПЗ 33 15, ПЗ 33 16, ПЗ 33 17, ПЗ 33 18, ПЗ 33 19, ПЗ 33 20, ПЗ 33 21, ПЗ 33 22, ПЗ 33 23, ПЗ 33 24, ПЗ 33 25, ПЗ 33 26, ПЗ 33 27, ПЗ 33 28, ПЗ 33 29, ПЗ 33 30, ПЗ 33 31, ПЗ 33 32, ПЗ 33 33, ПЗ 34 10, ПЗ 34 12 | G21: Местоположение | H21: 8 | I21: RusSet_Location | J21: Номер подобъекта (секции) | K21: RUS_Object_Sub | L21: Текстовый | M21: - | N21: С01 | O21: +
A22: Б.2 | B22: Непроизводственного назначения | C22: Объемно-планировочные и архитектурные решения | D22: IfcSpace | E22: Помещение | F22: ПЗ 30, ПЗ 30 10, ПЗ 30 20, ПЗ 30 30, ПЗ 31 01, ПЗ 31 02, ПЗ 31 03, ПЗ 31 04, ПЗ 31 05, ПЗ 31 06, ПЗ 31 07, ПЗ 31 08, ПЗ 31 09, ПЗ 31 10, ПЗ 31 12, ПЗ 31 13, ПЗ 31 14, ПЗ 31 15, ПЗ 31 16, ПЗ 31 17, ПЗ 32 10, ПЗ 32 12, ПЗ 32 13, ПЗ 32 14, ПЗ 32 15, ПЗ 32 16, ПЗ 33 10, ПЗ 33 12, ПЗ 33 13, ПЗ 33 14, ПЗ 33 15, ПЗ 33 16, ПЗ 33 17, ПЗ 33 18, ПЗ 33 19, ПЗ 33 20, ПЗ 33 21, ПЗ 33 22, ПЗ 33 23, ПЗ 33 24, ПЗ 33 25, ПЗ 33 26, ПЗ 33 27, ПЗ 33 28, ПЗ 33 29, ПЗ 33 30, ПЗ 33 31, ПЗ 33 32, ПЗ 33 33, ПЗ 34 10, ПЗ 34 12 | G22: Идентификация | H22: 9 | I22: RusSet_Identification | J22: Категория функциональной зоны | K22: RUS_Zone | L22: Текстовый | M22: - | N22: Жилая зона | O22: +
A23: Б.2 | B23: Непроизводственного назначения | C23: Объемно-планировочные и архитектурные решения | D23: IfcSpace | E23: Помещение | F23: ПЗ 30, ПЗ 30 10, ПЗ 30 20, ПЗ 30 30, ПЗ 31 01, ПЗ 31 02, ПЗ 31 03, ПЗ 31 04, ПЗ 31 05, ПЗ 31 06, ПЗ 31 07, ПЗ 31 08, ПЗ 31 09, ПЗ 31 10, ПЗ 31 12, ПЗ 31 13, ПЗ 31 14, ПЗ 31 15, ПЗ 31 16, ПЗ 31 17, ПЗ 32 10, ПЗ 32 12, ПЗ 32 13, ПЗ 32 14, ПЗ 32 15, ПЗ 32 16, ПЗ 33 10, ПЗ 33 12, ПЗ 33 13, ПЗ 33 14, ПЗ 33 15, ПЗ 33 16, ПЗ 33 17, ПЗ 33 18, ПЗ 33 19, ПЗ 33 20, ПЗ 33 21, ПЗ 33 22, ПЗ 33 23, ПЗ 33 24, ПЗ 33 25, ПЗ 33 26, ПЗ 33 27, ПЗ 33 28, ПЗ 33 29, ПЗ 33 30, ПЗ 33 31, ПЗ 33 32, ПЗ 33 33, ПЗ 34 10, ПЗ 34 12 | G23: Идентификация | H23: 10 | I23: RusSet_Identification | J23: Группа помещений | K23: RUS_Group_Type | L23: Текстовый | M23: - | N23: Квартира | O23: +
A24: Б.2 | B24: Непроизводственного назначения | C24: Объемно-планировочные и архитектурные решения | D24: IfcSpace | E24: Помещение | F24: ПЗ 30, ПЗ 30 10, ПЗ 30 20, ПЗ 30 30, ПЗ 31 01, ПЗ 31 02, ПЗ 31 03, ПЗ 31 04, ПЗ 31 05, ПЗ 31 06, ПЗ 31 07, ПЗ 31 08, ПЗ 31 09, ПЗ 31 10, ПЗ 31 12, ПЗ 31 13, ПЗ 31 14, ПЗ 31 15, ПЗ 31 16, ПЗ 31 17, ПЗ 32 10, ПЗ 32 12, ПЗ 32 13, ПЗ 32 14, ПЗ 32 15, ПЗ 32 16, ПЗ 33 10, ПЗ 33 12, ПЗ 33 13, ПЗ 33 14, ПЗ 33 15, ПЗ 33 16, ПЗ 33 17, ПЗ 33 18, ПЗ 33 19, ПЗ 33 20, ПЗ 33 21, ПЗ 33 22, ПЗ 33 23, ПЗ 33 24, ПЗ 33 25, ПЗ 33 26, ПЗ 33 27, ПЗ 33 28, ПЗ 33 29, ПЗ 33 30, ПЗ 33 31, ПЗ 33 32, ПЗ 33 33, ПЗ 34 10, ПЗ 34 12 | G24: Идентификация | H24: 11 | I24: RusSet_Identification | J24: Номер группы помещений | K24: RUS_Group_Number | L24: Текстовый | M24: - | N24: 12 | O24: +
A25: Б.2 | B25: Непроизводственного назначения | C25: Объемно-планировочные и архитектурные решения | D25: IfcSpace | E25: Помещение | F25: ПЗ 30, ПЗ 30 10, ПЗ 30 20, ПЗ 30 30, ПЗ 31 01, ПЗ 31 02, ПЗ 31 03, ПЗ 31 04, ПЗ 31 05, ПЗ 31 06, ПЗ 31 07, ПЗ 31 08, ПЗ 31 09, ПЗ 31 10, ПЗ 31 12, ПЗ 31 13, ПЗ 31 14, ПЗ 31 15, ПЗ 31 16, ПЗ 31 17, ПЗ 32 10, ПЗ 32 12, ПЗ 32 13, ПЗ 32 14, ПЗ 32 15, ПЗ 32 16, ПЗ 33 10, ПЗ 33 12, ПЗ 33 13, ПЗ 33 14, ПЗ 33 15, ПЗ 33 16, ПЗ 33 17, ПЗ 33 18, ПЗ 33 19, ПЗ 33 20, ПЗ 33 21, ПЗ 33 22, ПЗ 33 23, ПЗ 33 24, ПЗ 33 25, ПЗ 33 26, ПЗ 33 27, ПЗ 33 28, ПЗ 33 29, ПЗ 33 30, ПЗ 33 31, ПЗ 33 32, ПЗ 33 33, ПЗ 34 10, ПЗ 34 12 | G25: Идентификация | H25: 12 | I25: RusSet_Identification | J25: Номер помещения | K25: RUS_Number | L25: Текстовый | M25: - | N25: 1 | O25: +
A26: Б.2 | B26: Непроизводственного назначения | C26: Объемно-планировочные и архитектурные решения | D26: IfcSpace | E26: Помещение | F26: ПЗ 30, ПЗ 30 10, ПЗ 30 20, ПЗ 30 30, ПЗ 31 01, ПЗ 31 02, ПЗ 31 03, ПЗ 31 04, ПЗ 31 05, ПЗ 31 06, ПЗ 31 07, ПЗ 31 08, ПЗ 31 09, ПЗ 31 10, ПЗ 31 12, ПЗ 31 13, ПЗ 31 14, ПЗ 31 15, ПЗ 31 16, ПЗ 31 17, ПЗ 32 10, ПЗ 32 12, ПЗ 32 13, ПЗ 32 14, ПЗ 32 15, ПЗ 32 16, ПЗ 33 10, ПЗ 33 12, ПЗ 33 13, ПЗ 33 14, ПЗ 33 15, ПЗ 33 16, ПЗ 33 17, ПЗ 33 18, ПЗ 33 19, ПЗ 33 20, ПЗ 33 21, ПЗ 33 22, ПЗ 33 23, ПЗ 33 24, ПЗ 33 25, ПЗ 33 26, ПЗ 33 27, ПЗ 33 28, ПЗ 33 29, ПЗ 33 30, ПЗ 33 31, ПЗ 33 32, ПЗ 33 33, ПЗ 34 10, ПЗ 34 12 | G26: Материалы АГР | H26: 14 | I26: RusSet_AGR | J26: Подземный этаж | K26: RUS_BasementFloor | L26: Булевый | M26: - | N26: да/нет | O26: +
A27: Б.2 | B27: Непроизводственного назначения | C27: Объемно-планировочные и архитектурные решения | D27: IfcSpace | E27: Помещение | F27: ПЗ 30, ПЗ 30 10, ПЗ 30 20, ПЗ 30 30, ПЗ 31 01, ПЗ 31 02, ПЗ 31 03, ПЗ 31 04, ПЗ 31 05, ПЗ 31 06, ПЗ 31 07, ПЗ 31 08, ПЗ 31 09, ПЗ 31 10, ПЗ 31 12, ПЗ 31 13, ПЗ 31 14, ПЗ 31 15, ПЗ 31 16, ПЗ 31 17, ПЗ 32 10, ПЗ 32 12, ПЗ 32 13, ПЗ 32 14, ПЗ 32 15, ПЗ 32 16, ПЗ 33 10, ПЗ 33 12, ПЗ 33 13, ПЗ 33 14, ПЗ 33 15, ПЗ 33 16, ПЗ 33 17, ПЗ 33 18, ПЗ 33 19, ПЗ 33 20, ПЗ 33 21, ПЗ 33 22, ПЗ 33 23, ПЗ 33 24, ПЗ 33 25, ПЗ 33 26, ПЗ 33 27, ПЗ 33 28, ПЗ 33 29, ПЗ 33 30, ПЗ 33 31, ПЗ 33 32, ПЗ 33 33, ПЗ 34 10, ПЗ 34 12 | G27: Материалы АГР | H27: 15 | I27: RusSet_AGR | J27: Плавающая высотная отметка уровня | K27: RUS_GroundFloor | L27: Булевый | M27: - | N27: да/нет | O27: +
A28: Б.2 | B28: Непроизводственного назначения | C28: Объемно-планировочные и архитектурные решения | D28: IfcSpace | E28: Помещение | F28: ПЗ 30, ПЗ 30 10, ПЗ 30 20, ПЗ 30 30, ПЗ 31 01, ПЗ 31 02, ПЗ 31 03, ПЗ 31 04, ПЗ 31 05, ПЗ 31 06, ПЗ 31 07, ПЗ 31 08, ПЗ 31 09, ПЗ 31 10, ПЗ 31 12, ПЗ 31 13, ПЗ 31 14, ПЗ 31 15, ПЗ 31 16, ПЗ 31 17, ПЗ 32 10, ПЗ 32 12, ПЗ 32 13, ПЗ 32 14, ПЗ 32 15, ПЗ 32 16, ПЗ 33 10, ПЗ 33 12, ПЗ 33 13, ПЗ 33 14, ПЗ 33 15, ПЗ 33 16, ПЗ 33 17, ПЗ 33 18, ПЗ 33 19, ПЗ 33 20, ПЗ 33 21, ПЗ 33 22, ПЗ 33 23, ПЗ 33 24, ПЗ 33 25, ПЗ 33 26, ПЗ 33 27, ПЗ 33 28, ПЗ 33 29, ПЗ 33 30, ПЗ 33 31, ПЗ 33 32, ПЗ 33 33, ПЗ 34 10, ПЗ 34 12 | G28: Материалы АГР | H28: 16 | I28: RusSet_AGR | J28: Студия (тип квартиры) | K28: RUS_StudioApart | L28: Булевый | M28: - | N28: да/нет | O28: +
A29: Б.3.1 | B29: Непроизводственного назначения | C29: Объемно-планировочные и архитектурные решения | D29: IfcSpace | E29: Зона (СПП в ГНС) | G29: Общие данные | H29: 1 | I29: RusSet_Common | J29: Код помещения и зоны МССК | K29: RUS_MSSK_SpaceAndZone_Code | L29: Текстовый | M29: - | N29: - | O29: +
A30: Б.3.1 | B30: Непроизводственного назначения | C30: Объемно-планировочные и архитектурные решения | D30: IfcSpace | E30: Зона (СПП в ГНС) | G30: Общие данные | H30: 2 | I30: RusSet_Common | J30: Наименование | K30: RUS_Name | L30: Текстовый | M30: - | N30: СПП в ГНС | O30: +
A31: Б.3.1 | B31: Непроизводственного назначения | C31: Объемно-планировочные и архитектурные решения | D31: IfcSpace | E31: Зона (СПП в ГНС) | G31: Общие данные | H31: 3 | I31: RusSet_Common | J31: Наименование помещения и зоны МССК | K31: RUS_MSSK_SpaceAndZone_Name | L31: Текстовый | M31: - | N31: - | O31: +
A32: Б.3.1 | B32: Непроизводственного назначения | C32: Объемно-планировочные и архитектурные решения | D32: IfcSpace | E32: Зона (СПП в ГНС) | G32: Количественные параметры | H32: 4 | I32: RusSet_Quantities | J32: Высота | K32: RUS_Height | L32: Вещественный | M32: мм | N32: 3300 | O32: отменён
A33: Б.3.1 | B33: Непроизводственного назначения | C33: Объемно-планировочные и архитектурные решения | D33: IfcSpace | E33: Зона (СПП в ГНС) | G33: Количественные параметры | H33: 5 | I33: RusSet_Quantities | J33: Площадь | K33: RUS_Area | L33: Вещественный | M33: кв.м. | N33: 40 | O33: +
A34: Б.3.1 | B34: Непроизводственного назначения | C34: Объемно-планировочные и архитектурные решения | D34: IfcSpace | E34: Зона (СПП в ГНС) | G34: Количественные параметры | H34: 6 | I34: RusSet_Quantities | J34: Объем | K34: RUS_Volume | L34: Вещественный | M34: куб.м. | N34: 60 | O34: отменён
A35: Б.3.1 | B35: Непроизводственного назначения | C35: Объемно-планировочные и архитектурные решения | D35: IfcSpace | E35: Зона (СПП в ГНС) | G35: Местоположение | H35: 7 | I35: RusSet_Location | J35: Номер объекта (корпуса) | K35: RUS_Object | L35: Текстовый | M35: - | N35: К01 | O35: +
A36: Б.3.1 | B36: Непроизводственного назначения | C36: Объемно-планировочные и архитектурные решения | D36: IfcSpace | E36: Зона (СПП в ГНС) | G36: Местоположение | H36: 8 | I36: RusSet_Location | J36: Номер подобъекта (секции) | K36: RUS_Object_Sub | L36: Текстовый | M36: - | N36: С01 | O36: +
A37: Б.3.1 | B37: Непроизводственного назначения | C37: Объемно-планировочные и архитектурные решения | D37: IfcSpace | E37: Зона (СПП в ГНС) | G37: Идентификация | H37: 9 | I37: RusSet_Identification | J37: Категория функциональной зоны | K37: RUS_Zone | L37: Текстовый | M37: - | N37: СПП в ГНС | O37: +
A38: Б.3.1 | B38: Непроизводственного назначения | C38: Объемно-планировочные и архитектурные решения | D38: IfcSpace | E38: Зона (СПП в ГНС) | G38: Материалы АГР | H38: 10 | I38: RusSet_AGR | J38: Подземный этаж | K38: RUS_BasementFloor | L38: Булевый | M38: - | N38: да/нет | O38: +
A39: Б.3.1 | B39: Непроизводственного назначения | C39: Объемно-планировочные и архитектурные решения | D39: IfcSpace | E39: Зона (СПП в ГНС) | G39: Материалы АГР | H39: 11 | I39: RusSet_AGR | J39: Плавающая высотная отметка уровня | K39: RUS_GroundFloor | L39: Булевый | M39: - | N39: да/нет | O39: +
A40: Б.3.1 | B40: Непроизводственного назначения | C40: Объемно-планировочные и архитектурные решения | D40: IfcSpace | E40: Зона (СПП в ГНС) | G40: Материалы АГР | H40: 12 | I40: RusSet_AGR | J40: Жилая зона | K40: RUS_ResidentalRoom | L40: Булевый | M40: - | N40: да/нет | O40: +
...

Sheet СТ_Эл.
A1: Изм. | B1: +
A3: Элемент: | B3: Класс IFC: | C3: Набор атрибутов | D3: Имя параметра IFC | E3: Наименование параметра | F3: Тип данных | G3: Пример
A4: Вспомогательное 3D-тело | B4: IfcBuildingElementProxy | C4: RusSet_Common | D4: RUS_MSSK_Element_Code | E4: Код элемента МССК | F4: Текстовый | G4: ЭЛ 30 30
D5: RUS_MSSK_Element_Name | E5: Наименование элемента МССК | F5: Текстовый | G5: Подземная часть здания
D6: RUS_Name | E6: Наименование | F6: Текстовый | G6: Объем подземной части здания
C7: RusSet_Location | D7: RUS_Object | E7: Номер объекта (корпуса) | F7: Текстовый | G7: К01
D8: RUS_Object_Sub | E8: Номер подобъекта (секции) | F8: Текстовый | G8: С01
A10: Дверь, ворота, люк | B10: IfcDoor | C10: RusSet_Common | D10: RUS_MSSK_Element_Code | E10: Код элемента МССК | F10: Текстовый | G10: ЭЛ 30 18 30
D11: RUS_MSSK_Element_Name | E11: Наименование элемента МССК | F11: Текстовый | G11: Дверь
D12: RUS_MSSK_Material_Code
D13: RUS_MSSK_Material_Name
D14: RUS_Name | E14: Наименование | F14: Текстовый | G14: Ворота
C15: RusSet_Location | D15: RUS_Object | E15: Номер объекта (корпуса) | F15: Текстовый | G15: К01
D16: RUS_Object_Sub | E16: Номер подобъекта (секции) | F16: Текстовый | G16: С01
C17: RusSet_Quantities | D17: RUS_Height | E17: Высота | F17: Вещественный | G17: 2100
D18: RUS_Width | E18: Ширина | F18: Вещественный | G18: 1000
A20: Зона (Общая площадь) | B20: IfcSpace | C20: RusSet_AGR | D20: RUS_BasementFloor | E20: Подземный этаж | F20: Булевый | G20: да/нет
D21: RUS_GroundFloor | E21: Плавающая высотная отметка уровня | F21: Булевый | G21: да/нет
D22: RUS_ResidentalRoom | E22: Жилая зона | F22: Булевый | G22: да/нет
C23: RusSet_Common | D23: RUS_MSSK_SpaceAndZone_Code | E23: Код помещения и зоны МССК | F23: Текстовый | G23: ПЗ 03
D24: RUS_MSSK_SpaceAndZone_Name | E24: Наименование помещения и зоны МССК | F24: Текстовый | G24: Общая площадь
D25: RUS_Name | E25: Наименование | F25: Текстовый | G25: Общая площадь
C26: RusSet_Identification | D26: RUS_Zone | E26: Категория функциональной зоны | F26: Текстовый | G26: Общая площадь
C27: RusSet_Location | D27: RUS_Object | E27: Номер объекта (корпуса) | F27: Текстовый | G27: К01
D28: RUS_Object_Sub | E28: Номер подобъекта (секции) | F28: Текстовый | G28: С01
C29: RusSet_Quantities | D29: RUS_Area | E29: Площадь | F29: Вещественный | G29: 40
A30: Зона (СПП в ГНС) | B30: IfcSpace | C30: RusSet_AGR | D30: RUS_BasementFloor | E30: Подземный этаж | F30: Булевый | G30: да/нет
D31: RUS_GroundFloor | E31: Плавающая высотная отметка уровня | F31: Булевый | G31: да/нет
D32: RUS_ResidentalRoom | E32: Жилая зона | F32: Булевый | G32: да/нет
C33: RusSet_Common | D33: RUS_MSSK_SpaceAndZone_Code | E33: Код помещения и зоны МССК | F33: Текстовый | G33: -
D34: RUS_MSSK_SpaceAndZone_Name | E34: Наименование помещения и зоны МССК | F34: Текстовый | G34: -
D35: RUS_Name | E35: Наименование | F35: Текстовый | G35: СПП в ГНС
C36: RusSet_Identification | D36: RUS_Zone | E36: Категория функциональной зоны | F36: Текстовый | G36: СПП в ГНС
C37: RusSet_Location | D37: RUS_Object | E37: Номер объекта (корпуса) | F37: Текстовый | G37: К01
D38: RUS_Object_Sub | E38: Номер подобъекта (секции) | F38: Текстовый | G38: С01
C39: RusSet_Quantities | D39: RUS_Area | E39: Площадь | F39: Вещественный | G39: 40
A41: Импост витражной системы (навесного фасада) | B41: IfcMember | C41: RusSet_Common | D41: RUS_MSSK_Element_Code | E41: Код элемента МССК | F41: Текстовый | G41: ЭЛ 30 10 10 20
D42: RUS_MSSK_Material_Code
D43: RUS_MSSK_Material_Name
D44: RUS_Name | E44: Наименование | F44: Текстовый | G44: Импост витражной системы
...

Sheet СТ_Атр.
A1: Изм. | B1: +
A3: Имя параметра IFC | B3: Наименование параметра | C3: Набор атрибутов | D3: Класс IFC: | E3: Элемент: | F3: Тип данных | G3: Пример
A4: RUS_Area | B4: Площадь | C4: RusSet_Quantities | D4: IfcSpace | E4: Зона (Общая площадь) | F4: Вещественный | G4: 40
E5: Зона (СПП в ГНС) | F5: Вещественный | G5: 40
E6: Помещение | F6: Вещественный | G6: 40
A7: RUS_BasementFloor | B7: Подземный этаж | C7: RusSet_AGR | D7: IfcSpace | E7: Зона (Общая площадь) | F7: Булевый | G7: да/нет
E8: Зона (СПП в ГНС) | F8: Булевый | G8: да/нет
E9: Помещение | F9: Булевый | G9: да/нет
A10: RUS_BuildingAddress | B10: Адрес | C10: RusSet_Project | D10: IfcBuilding | E10: Объект | F10: Текстовый | G10: г. Москва, Проспект Мира
A11: RUS_Diametr | B11: Диаметр | C11: RusSet_Quantities | D11: IfcColumn | E11: Колонна, пилястра | F11: Вещественный | G11: 300
A12: RUS_FNO | B12: Функциональное назначение объекта | C12: RusSet_AGR | D12: IfcBuilding | E12: Объект | F12: Текстовый | G12: Жилое здание/Нежилое здание
A13: RUS_GroundFloor | B13: Плавающая высотная отметка уровня | C13: RusSet_AGR | D13: IfcSpace | E13: Зона (Общая площадь) | F13: Булевый | G13: да/нет
E14: Зона (СПП в ГНС) | F14: Булевый | G14: да/нет
E15: Помещение | F15: Булевый | G15: да/нет
A16: RUS_Group_Number | B16: Номер группы помещений | C16: RusSet_Identification | D16: IfcSpace | E16: Помещение | F16: Текстовый | G16: 12
A17: RUS_Group_Type | B17: Группа помещений | C17: RusSet_Identification | D17: IfcSpace | E17: Помещение | F17: Текстовый | G17: Квартира
A18: RUS_Height | B18: Высота | C18: RusSet_Quantities | D18: IfcColumn | E18: Колонна, пилястра | F18: Вещественный | G18: 600
D19: IfcDoor | E19: Дверь, ворота, люк | F19: Вещественный | G19: 2100
D20: IfcWall | E20: Стена, перегородка | F20: Вещественный | G20: 3300
D21: IfcWindow | E21: Окно, балконный блок, остекление витража | F21: Вещественный | G21: 2100
A22: RUS_Length | B22: Длина | C22: RusSet_Quantities | D22: IfcWall | E22: Стена, перегородка | F22: Вещественный | G22: 2100
A23: RUS_MSSK_Element_Code | B23: Код элемента МССК | C23: RusSet_Common | D23: IfcBuildingElementProxy | E23: Вспомогательное 3D-тело | F23: Текстовый | G23: ЭЛ 30 30
D24: IfcColumn | E24: Колонна, пилястра | F24: Текстовый | G24: ЭЛ 30 16 51
D25: IfcCurtainWall | E25: Фасад | F25: Текстовый | G25: ЭЛ 30 10 10
D26: IfcDoor | E26: Дверь, ворота, люк | F26: Текстовый | G26: ЭЛ 30 18 30
D27: IfcMember | E27: Импост витражной системы (навесного фасада) | F27: Текстовый | G27: ЭЛ 30 10 10 20
D28: IfcPlate | E28: Панель витражной системы (навесного фасада) | F28: Текстовый | G28: ЭЛ 30 10 10 10
D29: IfcRamp | E29: Пандус, рампа | F29: Текстовый | G29: ЭЛ 30 24 40
D30: IfcSlab | E30: Перекрытие | F30: Текстовый | G30: ЭЛ 30 10 40
D31: IfcStair | E31: Лестница | F31: Текстовый | G31: ЭЛ 30 24 30
D32: IfcWall | E32: Стена, перегородка | F32: Текстовый | G32: ЭЛ 30 10 20
D33: IfcWindow | E33: Окно, балконный блок, остекление витража | F33: Текстовый | G33: ЭЛ 30 18 40
A34: RUS_MSSK_Element_Name | B34: Наименование элемента МССК | C34: RusSet_Common | D34: IfcBuildingElementProxy | E34: Вспомогательное 3D-тело | F34: Текстовый | G34: Подземная часть здания
D35: IfcColumn | E35: Колонна, пилястра | F35: Текстовый | G35: Пилястра
D36: IfcCurtainWall | E36: Фасад | F36: Текстовый | G36: Витраж
D37: IfcDoor | E37: Дверь, ворота, люк | F37: Текстовый | G37: Дверь
D38: IfcPlate | E38: Панель витражной системы (навесного фасада) | F38: Текстовый | G38: Панель витражной систем
D39: IfcRamp | E39: Пандус, рампа | F39: Текстовый | G39: Пандус
D40: IfcSlab | E40: Перекрытие | F40: Текстовый | G40: Перекрытие
D41: IfcStair | E41: Лестница | F41: Текстовый | G41: Лестница
...

Sheet СТ_Наб.Атр.
A1: Изм. | B1: +
A3: Набор атрибутов | B3: Имя параметра IFC | C3: Наименование параметра | D3: Класс IFC: | E3: Элемент: | F3: Тип данных | G3: Пример | H3: Ед.изм.
A4: RusSet_AGR | B4: RUS_BasementFloor | C4: Подземный этаж | D4: IfcSpace | E4: Зона (Общая площадь) | F4: Булевый | G4: да/нет | H4: -
E5: Зона (СПП в ГНС) | F5: Булевый | G5: да/нет | H5: -
E6: Помещение | F6: Булевый | G6: да/нет | H6: -
B7: RUS_FNO | C7: Функциональное назначение объекта | D7: IfcBuilding | E7: Объект | F7: Текстовый | G7: Жилое здание/Нежилое здание | H7: -
B8: RUS_GroundFloor | C8: Плавающая высотная отметка уровня | D8: IfcSpace | E8: Зона (Общая площадь) | F8: Булевый | G8: да/нет | H8: -
E9: Зона (СПП в ГНС) | F9: Булевый | G9: да/нет | H9: -
E10: Помещение | F10: Булевый | G10: да/нет | H10: -
B11: RUS_ResidentalRoom | C11: Жилая зона | D11: IfcSpace | E11: Зона (Общая площадь) | F11: Булевый | G11: да/нет | H11: -
E12: Зона (СПП в ГНС) | F12: Булевый | G12: да/нет | H12: -
B13: RUS_StudioApart | C13: Студия (тип квартиры) | D13: IfcSpace | E13: Помещение | F13: Булевый | G13: да/нет | H13: -
A14: RusSet_Common | B14: RUS_MSSK_Element_Code | C14: Код элемента МССК | D14: IfcBuildingElementProxy | E14: Вспомогательное 3D-тело | F14: Текстовый | G14: ЭЛ 30 30 | H14: -
D15: IfcColumn | E15: Колонна, пилястра | F15: Текстовый | G15: ЭЛ 30 16 51 | H15: -
D16: IfcCurtainWall | E16: Фасад | F16: Текстовый | G16: ЭЛ 30 10 10 | H16: -
D17: IfcDoor | E17: Дверь, ворота, люк | F17: Текстовый | G17: ЭЛ 30 18 30 | H17: -
D18: IfcMember | E18: Импост витражной системы (навесного фасада) | F18: Текстовый | G18: ЭЛ 30 10 10 20 | H18: -
D19: IfcPlate | E19: Панель витражной системы (навесного фасада) | F19: Текстовый | G19: ЭЛ 30 10 10 10 | H19: -
D20: IfcRamp | E20: Пандус, рампа | F20: Текстовый | G20: ЭЛ 30 24 40 | H20: -
D21: IfcSlab | E21: Перекрытие | F21: Текстовый | G21: ЭЛ 30 10 40 | H21: -
D22: IfcStair | E22: Лестница | F22: Текстовый | G22: ЭЛ 30 24 30 | H22: -
D23: IfcWall | E23: Стена, перегородка | F23: Текстовый | G23: ЭЛ 30 10 20 | H23: -
D24: IfcWindow | E24: Окно, балконный блок, остекление витража | F24: Текстовый | G24: ЭЛ 30 18 40 | H24: -
B25: RUS_MSSK_Element_Name | C25: Наименование элемента МССК | D25: IfcBuildingElementProxy | E25: Вспомогательное 3D-тело | F25: Текстовый | G25: Подземная часть здания | H25: -
D26: IfcColumn | E26: Колонна, пилястра | F26: Текстовый | G26: Пилястра | H26: -
D27: IfcCurtainWall | E27: Фасад | F27: Текстовый | G27: Витраж | H27: -
D28: IfcDoor | E28: Дверь, ворота, люк | F28: Текстовый | G28: Дверь | H28: -
D29: IfcPlate | E29: Панель витражной системы (навесного фасада) | F29: Текстовый | G29: Панель витражной систем | H29: -
D30: IfcRamp | E30: Пандус, рампа | F30: Текстовый | G30: Пандус | H30: -
D31: IfcSlab | E31: Перекрытие | F31: Текстовый | G31: Перекрытие | H31: -
D32: IfcStair | E32: Лестница | F32: Текстовый | G32: Лестница | H32: -
D33: IfcWall | E33: Стена, перегородка | F33: Текстовый | G33: Перегородка | H33: -
D34: IfcWindow | E34: Окно, балконный блок, остекление витража | F34: Текстовый | G34: Окно | H34: -
B35: RUS_MSSK_Material_Code | C35: Код материала МССК | D35: IfcCurtainWall | E35: Фасад | F35: Текстовый | G35: СТ 00 70 | H35: -
D36: IfcDoor | E36: Дверь, ворота, люк | F36: Текстовый | G36: СТ 10 17 20 10 | H36: -
D37: IfcMember | E37: Импост витражной системы (навесного фасада) | F37: Текстовый | G37: СТ 00 80 | H37: -
D38: IfcPlate | E38: Панель витражной системы (навесного фасада) | F38: Текстовый | G38: СТ 00 80 | H38: -
D39: IfcWindow | E39: Окно, балконный блок, остекление витража | F39: Текстовый | G39: СТ 10 17 20 10 | H39: -
B40: RUS_MSSK_Material_Name | C40: Наименование материала МССК | D40: IfcCurtainWall | E40: Фасад | F40: Текстовый | G40: Стекло | H40: -
D41: IfcDoor | E41: Дверь, ворота, люк | F41: Текстовый | G41: Алюминий | H41: -
...

Sheet СТ_Наб.Атр (кратко)
A1: Изм. | B1: +
A3: Набор атрибутов | B3: Имя параметра IFC | C3: Наименование параметра | D3: Тип данных | E3: Ед.изм.
A4: RusSet_AGR | B4: RUS_BasementFloor | C4: Подземный этаж | D4: Булевый | E4: -
B5: RUS_FNO | C5: Функциональное назначение объекта | D5: Текстовый | E5: -
B6: RUS_GroundFloor | C6: Плавающая высотная отметка уровня | D6: Булевый | E6: -
B7: RUS_ResidentalRoom | C7: Жилая зона | D7: Булевый | E7: -
B8: RUS_StudioApart | C8: Студия (тип квартиры) | D8: Булевый | E8: -
A9: RusSet_Common | B9: RUS_MSSK_Element_Code | C9: Код элемента МССК | D9: Текстовый | E9: -
B10: RUS_MSSK_Element_Name | C10: Наименование элемента МССК | D10: Текстовый | E10: -
B11: RUS_MSSK_Material_Code | C11: Код материала МССК | D11: Текстовый | E11: -
B12: RUS_MSSK_Material_Name | C12: Наименование материала МССК | D12: Текстовый | E12: -
B13: RUS_MSSK_SpaceAndZone_Code | C13: Код помещения и зоны МССК | D13: Текстовый | E13: -
B14: RUS_MSSK_SpaceAndZone_Name | C14: Наименование помещения и зоны МССК | D14: Текстовый | E14: -
B15: RUS_Name | C15: Наименование | D15: Текстовый | E15: -
A16: RusSet_Identification | B16: RUS_Group_Number | C16: Номер группы помещений | D16: Текстовый | E16: -
B17: RUS_Group_Type | C17: Группа помещений | D17: Текстовый | E17: -
B18: RUS_Number | C18: Номер помещения | D18: Текстовый | E18: -
B19: RUS_Zone | C19: Категория функциональной зоны | D19: Текстовый | E19: -
A20: RusSet_Location | B20: RUS_Object | C20: Номер объекта (корпуса) | D20: Текстовый | E20: -
B21: RUS_Object_Sub | C21: Номер подобъекта (секции) | D21: Текстовый | E21: -
A22: RusSet_Project | B22: RUS_BuildingAddress | C22: Адрес | D22: Текстовый | E22: -
B23: RUS_ProjectName | C23: Наименование проекта | D23: Текстовый | E23: -
A24: RusSet_Quantities | B24: RUS_Area | C24: Площадь | D24: Вещественный | E24: кв.м.
B25: RUS_Diametr | C25: Диаметр | D25: Вещественный | E25: мм
B26: RUS_Height | C26: Высота | D26: Вещественный | E26: мм
B27: RUS_Length | C27: Длина | D27: Вещественный | E27: мм
B28: RUS_Slope | C28: Уклон | D28: Вещественный | E28: ˚
B29: RUS_Thickness | C29: Толщина | D29: Вещественный | E29: мм
B30: RUS_Volume | C30: Объем | D30: Вещественный | E30: куб.м.
B31: RUS_Width | C31: Ширина | D31: Вещественный | E31: мм

Sheet СТ_МССК
A1: Изм. | B1: +
A3: Класс IFC: | B3: Код МССК:
A4: IfcBuildingElementProxy | B4: ЭЛ 30 30 10, ЭЛ 30 30 20
A5: IfcColumn | B5: ЭЛ 30 16 15, ЭЛ 30 16 25, ЭЛ 30 16 40, ЭЛ 30 16 42, ЭЛ 30 16 50, ЭЛ 30 16 51
A6: IfcCurtainWall | B6: ЭЛ 30 10 10, ЭЛ 30 10 35, ЭЛ 30 10 60, ЭЛ 30 10 61
A7: IfcDoor | B7: ЭЛ 30 18 20, ЭЛ 30 18 20 01, ЭЛ 30 18 20 02, ЭЛ 30 18 30, ЭЛ 30 18 30 10, ЭЛ 30 18 30 20, ЭЛ 30 18 30 30, ЭЛ 30 18 30 31, ЭЛ 30 18 50, ЭЛ 30 18 50 10, ЭЛ 30 18 50 20, ЭЛ 35 01 01, ЭЛ 35 01 02, ЭЛ 40 50 27 06
A8: IfcMember | B8: ЭЛ 30 10 10 20, ЭЛ 30 10 61 02
A9: IfcRamp | B9: ЭЛ 30 24 40, ЭЛ 30 24 60
A10: IfcSlab | B10: ЭЛ 30 10 40, ЭЛ 30 10 56, ЭЛ 30 10 57, ЭЛ 30 10 58, ЭЛ 30 10 80, ЭЛ 30 16 25, ЭЛ 30 24 20, ЭЛ 30 24 50, ЭЛ 30 24 51, ЭЛ 60 20 13
A11: IfcSpace | B11: ПЗ 03
B12: ПЗ 30, ПЗ 30 10, ПЗ 30 20, ПЗ 30 30, ПЗ 31 01, ПЗ 31 02, ПЗ 31 03, ПЗ 31 04, ПЗ 31 05, ПЗ 31 06, ПЗ 31 07, ПЗ 31 08, ПЗ 31 09, ПЗ 31 10, ПЗ 31 12, ПЗ 31 13, ПЗ 31 14, ПЗ 31 15, ПЗ 31 16, ПЗ 31 17, ПЗ 32 10, ПЗ 32 12, ПЗ 32 13, ПЗ 32 14, ПЗ 32 15, ПЗ 32 1
A13: IfcStair | B13: ЭЛ 30 24 30, ЭЛ 30 24 35
A14: IfcWall | B14: ЭЛ 20 20 06, ЭЛ 30 10 15, ЭЛ 30 10 20, ЭЛ 30 10 36, ЭЛ 30 10 75, ЭЛ 30 10 76, ЭЛ 30 10 77, ЭЛ 30 10 78, ЭЛ 30 10 79, ЭЛ 30 16 77, ЭЛ 30 16 78
A15: IfcWindow | B15: ЭЛ 20 30 24, ЭЛ 30 18 09, ЭЛ 30 18 40, ЭЛ 30 18 52, ЭЛ 30 18 52 10

Sheet МССК_СВОД
A1: Упомянутые в Приказе коды
A2: Класс IFC: | B2: Код МССК: | C2: Класс элемента/Группа помещений | D2: Подкласс элемента/Помещение | E2: Наименование МССК | F2: Совмещённое название
A3: IfcBuildingElementProxy | B3: ЭЛ 30 30 10 | C3: =VLOOKUP(B3,'МССК-7 (Эл.)'!$A$2:$F$944,4) -> Объем подземной части | D3: =VLOOKUP(B3,'МССК-7 (Эл.)'!$A$2:$F$944,5) -> 0 | E3: =IF(D3=0,C3,D3) -> Объем подземной части | F3: =E3&" - "&B3&"" -> Объем подземной части - ЭЛ 30 30 10
A4: IfcBuildingElementProxy | B4: ЭЛ 30 30 20 | C4: =VLOOKUP(B4,'МССК-7 (Эл.)'!$A$2:$F$944,4) -> Объем надземной части | D4: =VLOOKUP(B4,'МССК-7 (Эл.)'!$A$2:$F$944,5) -> 0 | E4: =IF(D4=0,C4,D4) -> Объем надземной части | F4: =E4&" - "&B4&"" -> Объем надземной части - ЭЛ 30 30 20
A5: IfcColumn | B5: ЭЛ 30 16 15 | C5: =VLOOKUP(B5,'МССК-7 (Эл.)'!$A$2:$F$944,4) -> База колонны | D5: =VLOOKUP(B5,'МССК-7 (Эл.)'!$A$2:$F$944,5) -> 0 | E5: =IF(D5=0,C5,D5) -> База колонны | F5: =E5&" - "&B5&"" -> База колонны - ЭЛ 30 16 15
A6: IfcColumn | B6: ЭЛ 30 16 25 | C6: =VLOOKUP(B6,'МССК-7 (Эл.)'!$A$2:$F$944,4) -> Капитель | D6: =VLOOKUP(B6,'МССК-7 (Эл.)'!$A$2:$F$944,5) -> 0 | E6: =IF(D6=0,C6,D6) -> Капитель | F6: =E6&" - "&B6&"" -> Капитель - ЭЛ 30 16 25
A7: IfcColumn | B7: ЭЛ 30 16 40 | C7: =VLOOKUP(B7,'МССК-7 (Эл.)'!$A$2:$F$944,4) -> Колонна | D7: =VLOOKUP(B7,'МССК-7 (Эл.)'!$A$2:$F$944,5) -> 0 | E7: =IF(D7=0,C7,D7) -> Колонна | F7: =E7&" - "&B7&"" -> Колонна - ЭЛ 30 16 40
A8: IfcColumn | B8: ЭЛ 30 16 42 | C8: =VLOOKUP(B8,'МССК-7 (Эл.)'!$A$2:$F$944,4) -> Фахверк | D8: =VLOOKUP(B8,'МССК-7 (Эл.)'!$A$2:$F$944,5) -> 0 | E8: =IF(D8=0,C8,D8) -> Фахверк | F8: =E8&" - "&B8&"" -> Фахверк - ЭЛ 30 16 42
A9: IfcColumn | B9: ЭЛ 30 16 50 | C9: =VLOOKUP(B9,'МССК-7 (Эл.)'!$A$2:$F$944,4) -> Пилон | D9: =VLOOKUP(B9,'МССК-7 (Эл.)'!$A$2:$F$944,5) -> 0 | E9: =IF(D9=0,C9,D9) -> Пилон | F9: =E9&" - "&B9&"" -> Пилон - ЭЛ 30 16 50
A10: IfcColumn | B10: ЭЛ 30 16 51 | C10: =VLOOKUP(B10,'МССК-7 (Эл.)'!$A$2:$F$944,4) -> Пилястра | D10: =VLOOKUP(B10,'МССК-7 (Эл.)'!$A$2:$F$944,5) -> 0 | E10: =IF(D10=0,C10,D10) -> Пилястра | F10: =E10&" - "&B10&"" -> Пилястра - ЭЛ 30 16 51
A11: IfcCurtainWall | B11: ЭЛ 30 10 10 | C11: =VLOOKUP(B11,'МССК-7 (Эл.)'!$A$2:$F$944,4) -> Витраж | D11: =VLOOKUP(B11,'МССК-7 (Эл.)'!$A$2:$F$944,5) -> 0 | E11: =IF(D11=0,C11,D11) -> Витраж | F11: =E11&" - "&B11&"" -> Витраж - ЭЛ 30 10 10
A12: IfcCurtainWall | B12: ЭЛ 30 10 35 | C12: =VLOOKUP(B12,'МССК-7 (Эл.)'!$A$2:$F$944,4) -> Панель навесная | D12: =VLOOKUP(B12,'МССК-7 (Эл.)'!$A$2:$F$944,5) -> 0 | E12: =IF(D12=0,C12,D12) -> Панель навесная | F12: =E12&" - "&B12&"" -> Панель навесная - ЭЛ 30 10 35
A13: IfcCurtainWall | B13: ЭЛ 30 10 60 | C13: =VLOOKUP(B13,'МССК-7 (Эл.)'!$A$2:$F$944,4) -> Фасад | D13: =VLOOKUP(B13,'МССК-7 (Эл.)'!$A$2:$F$944,5) -> 0 | E13: =IF(D13=0,C13,D13) -> Фасад | F13: =E13&" - "&B13&"" -> Фасад - ЭЛ 30 10 60
A14: IfcCurtainWall | B14: ЭЛ 30 10 61 | C14: =VLOOKUP(B14,'МССК-7 (Эл.)'!$A$2:$F$944,4) -> Навесная фасадная система | D14: =VLOOKUP(B14,'МССК-7 (Эл.)'!$A$2:$F$944,5) -> 0 | E14: =IF(D14=0,C14,D14) -> Навесная фасадная система | F14: =E14&" - "&B14&"" -> Навесная фасадная система - ЭЛ 30 10 61
... A38: IfcSlab | B38: ЭЛ 30 10 80 | C38: =VLOOKUP(B38,'МССК-7 (Эл.)'!$A$2:$F$944,4) -> Плита перекрытия | D38: =VLOOKUP(B38,'МССК-7 (Эл.)'!$A$2:$F$944,5) -> 0 | E38: =IF(D38=0,C38,D38) -> Плита перекрытия | F38: =E38&" - "&B38&"" -> Плита перекрытия - ЭЛ 30 10 80
A39: IfcSlab | B39: ЭЛ 30 16 25 | C39: =VLOOKUP(B39,'МССК-7 (Эл.)'!$A$2:$F$944,4) -> Капитель | D39: =VLOOKUP(B39,'МССК-7 (Эл.)'!$A$2:$F$944,5) -> 0 | E39: =IF(D39=0,C39,D39) -> Капитель | F39: o
A40: IfcSlab | B40: ЭЛ 30 24 20 | C40: =VLOOKUP(B40,'МССК-7 (Эл.)'!$A$2:$F$944,4) -> Лестничная площадка | D40: =VLOOKUP(B40,'МССК-7 (Эл.)'!$A$2:$F$944,5) -> 0 | E40: =IF(D40=0,C40,D40) -> Лестничная площадка | F40: =E40&" - "&B40&"" -> Лестничная площадка - ЭЛ 30 24 20
A41: IfcSlab | B41: ЭЛ 30 24 50 | C41: =VLOOKUP(B41,'МССК-7 (Эл.)'!$A$2:$F$944,4) -> Горизонтальная площадка пандуса | D41: =VLOOKUP(B41,'МССК-7 (Эл.)'!$A$2:$F$944,5) -> 0 | E41: =IF(D41=0,C41,D41) -> Горизонтальная площадка пандуса | F41: =E41&" - "&B41&"" -> Горизонтальная площадка пандуса - ЭЛ 30 24 50
A42: IfcSlab | B42: ЭЛ 30 24 51 | C42: =VLOOKUP(B42,'МССК-7 (Эл.)'!$A$2:$F$944,4) -> Горизонтальная площадка рампы | D42: =VLOOKUP(B42,'МССК-7 (Эл.)'!$A$2:$F$944,5) -> 0 | E42: =IF(D42=0,C42,D42) -> Горизонтальная площадка рампы | F42: =E42&" - "&B42&"" -> Горизонтальная площадка рампы - ЭЛ 30 24 51
A43: IfcSlab | B43: ЭЛ 60 20 13 | C43: =VLOOKUP(B43,'МССК-7 (Эл.)'!$A$2:$F$944,4) -> Путевая плита | D43: =VLOOKUP(B43,'МССК-7 (Эл.)'!$A$2:$F$944,5) -> 0 | E43: =IF(D43=0,C43,D43) -> Путевая плита | F43: =E43&" - "&B43&"" -> Путевая плита - ЭЛ 60 20 13
A44: IfcStair | B44: ЭЛ 30 24 30 | C44: =VLOOKUP(B44,'МССК-7 (Эл.)'!$A$2:$F$944,4) -> Лестница | D44: =VLOOKUP(B44,'МССК-7 (Эл.)'!$A$2:$F$944,5) -> 0 | E44: =IF(D44=0,C44,D44) -> Лестница | F44: =E44&" - "&B44&"" -> Лестница - ЭЛ 30 24 30
A45: IfcStair | B45: ЭЛ 30 24 35 | C45: =VLOOKUP(B45,'МССК-7 (Эл.)'!$A$2:$F$944,4) -> Лестница-трап | D45: =VLOOKUP(B45,'МССК-7 (Эл.)'!$A$2:$F$944,5) -> 0 | E45: =IF(D45=0,C45,D45) -> Лестница-трап | F45: =E45&" - "&B45&"" -> Лестница-трап - ЭЛ 30 24 35
A46: IfcWall | B46: ЭЛ 20 20 06 | C46: =VLOOKUP(B46,'МССК-7 (Эл.)'!$A$2:$F$944,4) -> Парапет кровли | D46: =VLOOKUP(B46,'МССК-7 (Эл.)'!$A$2:$F$944,5) -> 0 | E46: =IF(D46=0,C46,D46) -> Парапет кровли | F46: =E46&" - "&B46&"" -> Парапет кровли - ЭЛ 20 20 06
A47: IfcWall | B47: ЭЛ 30 10 15 | C47: =VLOOKUP(B47,'МССК-7 (Эл.)'!$A$2:$F$944,4) -> Стена | D47: =VLOOKUP(B47,'МССК-7 (Эл.)'!$A$2:$F$944,5) -> 0 | E47: =IF(D47=0,C47,D47) -> Стена | F47: =E47&" - "&B47&"" -> Стена - ЭЛ 30 10 15
A48: IfcWall | B48: ЭЛ 30 10 20 | C48: =VLOOKUP(B48,'МССК-7 (Эл.)'!$A$2:$F$944,4) -> Перегородка | D48: =VLOOKUP(B48,'МССК-7 (Эл.)'!$A$2:$F$944,5) -> 0 | E48: =IF(D48=0,C48,D48) -> Перегородка | F48: =E48&" - "&B48&"" -> Перегородка - ЭЛ 30 10 20
A49: IfcWall | B49: ЭЛ 30 10 36 | C49: =VLOOKUP(B49,'МССК-7 (Эл.)'!$A$2:$F$944,4) -> Парапет | D49: =VLOOKUP(B49,'МССК-7 (Эл.)'!$A$2:$F$944,5) -> 0 | E49: =IF(D49=0,C49,D49) -> Парапет | F49: =E49&" - "&B49&"" -> Парапет - ЭЛ 30 10 36
A50: IfcWall | B50: ЭЛ 30 10 75 | C50: =VLOOKUP(B50,'МССК-7 (Эл.)'!$A$2:$F$944,4) -> Панель стеновая наружная рядовая | D50: =VLOOKUP(B50,'МССК-7 (Эл.)'!$A$2:$F$944,5) -> 0 | E50: =IF(D50=0,C50,D50) -> Панель стеновая наружная рядовая | F50: =E50&" - "&B50&"" -> Панель стеновая наружная рядовая - ЭЛ 30 10 75
A51: IfcWall | B51: ЭЛ 30 10 76 | C51: =VLOOKUP(B51,'МССК-7 (Эл.)'!$A$2:$F$944,4) -> Панель стеновая наружная простеночная | D51: =VLOOKUP(B51,'МССК-7 (Эл.)'!$A$2:$F$944,5) -> 0 | E51: =IF(D51=0,C51,D51) -> Панель стеновая наружная простеночная | F51: =E51&" - "&B51&"" -> Панель стеновая наружная простеночная - ЭЛ 30 10 76
... A61: IfcWindow | B61: ЭЛ 30 18 52 10 | C61: =VLOOKUP(B61,'МССК-7 (Эл.)'!$A$2:$F$944,4) -> Фонарь зенитный | D61: =VLOOKUP(B61,'МССК-7 (Эл.)'!$A$2:$F$944,5) -> Панель оконная фонарная | E61: =IF(D61=0,C61,D61) -> Панель оконная фонарная | F61: =E61&" - "&B61&"" -> Панель оконная фонарная - ЭЛ 30 18 52 10
A67: Материалы | B67: СТ 00 20 | C67: =VLOOKUP($B67,'МССК-8 (Мат.)'!$A$2:$F$944,3) -> Дерево | D67: =VLOOKUP($B67,'МССК-8 (Мат.)'!$A$2:$F$944,4) | E67: =IF(OR(D67=" ",D67="",D67=0),C67,D67) -> Дерево | F67: =E67&" - "&B67&"" -> Дерево - СТ 00 20
A68: Материалы | B68: СТ 00 30 | C68: =VLOOKUP($B68,'МССК-8 (Мат.)'!$A$2:$F$944,3) -> Камень | D68: =VLOOKUP($B68,'МССК-8 (Мат.)'!$A$2:$F$944,4) | E68: =IF(OR(D68=" ",D68="",D68=0),C68,D68) -> Камень | F68: =E68&" - "&B68&"" -> Камень - СТ 00 30
A69: Материалы | B69: СТ 00 40 | C69: =VLOOKUP($B69,'МССК-8 (Мат.)'!$A$2:$F$944,3) -> Кирпич | D69: =VLOOKUP($B69,'МССК-8 (Мат.)'!$A$2:$F$944,4) | E69: =IF(OR(D69=" ",D69="",D69=0),C69,D69) -> Кирпич | F69: =E69&" - "&B69&"" -> Кирпич - СТ 00 40
A70: Материалы | B70: СТ 00 50 | C70: =VLOOKUP($B70,'МССК-8 (Мат.)'!$A$2:$F$944,3) -> Композит | D70: =VLOOKUP($B70,'МССК-8 (Мат.)'!$A$2:$F$944,4) | E70: =IF(OR(D70=" ",D70="",D70=0),C70,D70) -> Композит | F70: =E70&" - "&B70&"" -> Композит - СТ 00 50
A71: Материалы | B71: СТ 00 60 | C71: =VLOOKUP($B71,'МССК-8 (Мат.)'!$A$2:$F$944,3) -> Сталь | D71: =VLOOKUP($B71,'МССК-8 (Мат.)'!$A$2:$F$944,4) | E71: =IF(OR(D71=" ",D71="",D71=0),C71,D71) -> Сталь | F71: =E71&" - "&B71&"" -> Сталь - СТ 00 60
A72: Материалы | B72: СТ 00 70 | C72: =VLOOKUP($B72,'МССК-8 (Мат.)'!$A$2:$F$944,3) -> Стекло | D72: =VLOOKUP($B72,'МССК-8 (Мат.)'!$A$2:$F$944,4) | E72: =IF(OR(D72=" ",D72="",D72=0),C72,D72) -> Стекло | F72: =E72&" - "&B72&"" -> Стекло - СТ 00 70
A73: Материалы | B73: СТ 00 80 | C73: =VLOOKUP($B73,'МССК-8 (Мат.)'!$A$2:$F$944,3) -> Пластмасса | D73: =VLOOKUP($B73,'МССК-8 (Мат.)'!$A$2:$F$944,4) | E73: =IF(OR(D73=" ",D73="",D73=0),C73,D73) -> Пластмасса | F73: =E73&" - "&B73&"" -> Пластмасса - СТ 00 80
A74: Материалы | B74: СТ 10 02 20 | C74: =VLOOKUP($B74,'МССК-8 (Мат.)'!$A$2:$F$944,3) -> Металл | D74: =VLOOKUP($B74,'МССК-8 (Мат.)'!$A$2:$F$944,4) -> Цветные металлы, сплавы | E74: =IF(OR(D74=" ",D74="",D74=0),C74,D74) -> Цветные металлы, сплавы | F74: =E74&" - "&B74&"" -> Цветные металлы, сплавы - СТ 10 02 20
A75: Материалы | B75: СТ 10 13 30 | C75: =VLOOKUP($B75,'МССК-8 (Мат.)'!$A$2:$F$944,3) -> Отделочные материалы | D75: =VLOOKUP($B75,'МССК-8 (Мат.)'!$A$2:$F$944,4) -> Штукатурные растворы | E75: =IF(OR(D75=" ",D75="",D75=0),C75,D75) -> Штукатурные растворы | F75: =E75&" - "&B75&"" -> Штукатурные растворы - СТ 10 13 30
A76: Материалы | B76: СТ 10 13 10 30 | C76: =VLOOKUP($B76,'МССК-8 (Мат.)'!$A$2:$F$944,3) -> Отделочные материалы | D76: =VLOOKUP($B76,'МССК-8 (Мат.)'!$A$2:$F$944,4) -> Отделочные материалы фасадов | E76: =IF(OR(D76=" ",D76="",D76=0),C76,D76) -> Отделочные материалы фасадов | F76: =E76&" - "&B76&"" -> Отделочные материалы фасадов - СТ 10 13 10 30
A82: IfcSpace | B82: ПЗ 03 | C82: =VLOOKUP($B82,'МССК-5 (Пом.)'!$A$2:$D$641,2) -> Общая площадь | D82: =VLOOKUP($B82,'МССК-5 (Пом.)'!$A$2:$D$641,3) -> 0 | E82: =IF(D82=0,C82,D82) -> Общая площадь | F82: =E82&" - "&B82&"" -> Общая площадь - ПЗ 03
...

Sheet МССК-5 (Пом.)
A1: КЛАССИФИКАТОРЫ ДЛЯ ИНФОРМАЦИОННОГО МОДЕЛИРОВАНИЯ. Часть 5. КЛАССИФИКАТОР «ПОМЕЩЕНИЯ И ЗОНЫ». Москва 2024
A2: Код | B2: Категория зон или группы помещений | C2: Группа помещений или помещение | D2: Помещение
A3: ПЗ 01 | B3: Границы земельного участка
A4: ПЗ 02 | B4: Площадь застройки
A5: ПЗ 03 | B5: Общая площадь
A6: ПЗ 03 10 | B6: Общая площадь | C6: Зоны участков
A7: ПЗ 03 10 01 | B7: Общая площадь | C7: Зоны участков | D7: Зона участка застройки
A8: ПЗ 03 10 02 | B8: Общая площадь | C8: Зоны участков | D8: Зона участка земельного
A9: ПЗ 04 | B9: Пожарный отсек
A10: ПЗ 05 | B10: Пожарная секция
A11: ПЗ 06 | B11: Зона безопасности МГН
A12: ПЗ 07 | B12: Зона санитарно-бытовая МГН
A13: ПЗ 08 | B13: Квартира
A14: ПЗ 09 | B14: Квартира МГН
A15: ПЗ 10 | B15: Наземная автостоянка
A16: ПЗ 10 10 | B16: Наземная автостоянка | C16: Надземная зона остановки и стоянки автомобильных транспортных средств
A17: ПЗ 10 10 01 | B17: Наземная автостоянка | C17: Надземная зона остановки и стоянки автомобильных транспортных средств | D17: Парковочное место надземное
A18: ПЗ 11 | B18: Подземная автостоянка
A19: ПЗ 11 10 | B19: Подземная автостоянка | C19: Подземная зона остановки и стоянки автомобильных транспортных средств
A20: ПЗ 11 10 01 | B20: Подземная автостоянка | C20: Подземная зона остановки и стоянки автомобильных транспортных средств | D20: Парковочное место поздемное
A21: ПЗ 12 | B21: Зона отдыха
A22: ПЗ 13 | B22: Зона ожидания
A23: ПЗ 14 | B23: Зоны организации строительства
A24: ПЗ 14 01 | B24: Зоны организации строительства | C24: Зона обслуживания
A25: ПЗ 14 02 | B25: Зоны организации строительства | C25: Зона действия строительных машин
A26: ПЗ 14 03 | B26: Зоны организации строительства | C26: Зона строительной площадки опасная производственная
A27: ПЗ 14 04 | B27: Зоны организации строительства | C27: Зона размещения складских площадок
A28: ПЗ 14 05 | B28: Зоны организации строительства | C28: Зона временного размещения грунта
A29: ПЗ 14 06 | B29: Зоны организации строительства | C29: Зона размещения строительной техники
A30: ПЗ 14 07 | B30: Зоны организации строительства | C30: Зона путей перемещения крана
A31: ПЗ 14 08 | B31: Зоны организации строительства | C31: Зона перемещения транспортных средств
A32: ПЗ 14 09 | B32: Зоны организации строительства | C32: Опасная зона
A33: ПЗ 15 | B33: Учебная зона
A34: ПЗ 16 | B34: Игровая зона
A35: ПЗ 17 | B35: Входная группа
A36: ПЗ 17 01 | B36: Входная группа | C36: Входная площадка
A37: ПЗ 18 | B37: Гардеробная
A38: ПЗ 19 | B38: Наружная зона
A39: ПЗ 19 01 | B39: Наружная зона | C39: Приямок
A40: ПЗ 19 02 | B40: Наружная зона | C40: Игровая площадка
...

Sheet МССК-7 (Эл.)
A1: КЛАССИФИКАТОРЫ ДЛЯ ИНФОРМАЦИОННОГО МОДЕЛИРОВАНИЯ. Часть 7. КЛАССИФИКАТОР «ЭЛЕМЕНТЫ». Москва 2024
A2: Код | B2: Категория элементов | C2: Назначение элементов | D2: Класс элемента | E2: Подкласс элемента | F2: класс IFC
A3: ЭЛ 10 | B3: Земляные сооружения, фундаменты
A4: ЭЛ 10 10 | B4: Земляные сооружения, фундаменты | C4: Фундаменты
A5: ЭЛ 10 10 10 | B5: Земляные сооружения, фундаменты | C5: Фундаменты | D5: Свая | F5: IfcPile
A6: ЭЛ 10 10 10 01 | B6: Земляные сооружения, фундаменты | C6: Фундаменты | D6: Свая | E6: Свая забивная | F6: IfcPile
A7: ЭЛ 10 10 10 02 | B7: Земляные сооружения, фундаменты | C7: Фундаменты | D7: Свая | E7: Свая набивная | F7: IfcPile
A8: ЭЛ 10 10 10 03 | B8: Земляные сооружения, фундаменты | C8: Фундаменты | D8: Свая | E8: Свая-оболочка | F8: IfcPile
A9: ЭЛ 10 10 10 04 | B9: Земляные сооружения, фундаменты | C9: Фундаменты | D9: Свая | E9: Свая буровая | F9: IfcPile
A10: ЭЛ 10 10 10 05 | B10: Земляные сооружения, фундаменты | C10: Фундаменты | D10: Свая | E10: Свая винтовая | F10: IfcPile
A11: ЭЛ 10 10 12 | B11: Земляные сооружения, фундаменты | C11: Фундаменты | D11: Ростверк | F11: IfcFooting
A12: ЭЛ 10 10 12 01 | B12: Земляные сооружения, фундаменты | C12: Фундаменты | D12: Ростверк | E12: Ростверк ленточный | F12: IfcFooting
A13: ЭЛ 10 10 12 02 | B13: Земляные сооружения, фундаменты | C13: Фундаменты | D13: Ростверк | E13: Ростверк столбчатый | F13: IfcFooting
A14: ЭЛ 10 10 12 03 | B14: Земляные сооружения, фундаменты | C14: Фундаменты | D14: Ростверк | E14: Балка ростверка | F14: IfcFooting
A15: ЭЛ 10 10 12 04 | B15: Земляные сооружения, фундаменты | C15: Фундаменты | D15: Ростверк | E15: Ростверк плитный | F15: IfcSlab
A16: ЭЛ 10 10 30 | B16: Земляные сооружения, фундаменты | C16: Фундаменты | D16: Фундамент общего назначения | F16: IfcFooting
A17: ЭЛ 10 10 30 01 | B17: Земляные сооружения, фундаменты | C17: Фундаменты | D17: Фундамент общего назначения | E17: Фундамент ленточный | F17: IfcFooting
A18: ЭЛ 10 10 30 02 | B18: Земляные сооружения, фундаменты | C18: Фундаменты | D18: Фундамент общего назначения | E18: Фундамент столбчатый | F18: IfcFooting
A19: ЭЛ 10 10 30 03 | B19: Земляные сооружения, фундаменты | C19: Фундаменты | D19: Фундамент общего назначения | E19: Фундаментная балка | F19: IfcFooting
A20: ЭЛ 10 10 30 04 | B20: Земляные сооружения, фундаменты | C20: Фундаменты | D20: Фундамент общего назначения | E20: Фундаментная плита | F20: IfcSlab
A21: ЭЛ 10 10 40 | B21: Земляные сооружения, фундаменты | C21: Фундаменты | D21: Фундаментный блок | F21: IfcFooting
A22: ЭЛ 10 10 40 01 | B22: Земляные сооружения, фундаменты | C22: Фундаменты | D22: Фундаментный блок | E22: Фундаментный блок сплошной | F22: IfcFooting
A23: ЭЛ 10 10 40 02 | B23: Земляные сооружения, фундаменты | C23: Фундаменты | D23: Фундаментный блок | E23: Фундаментный блок с вырезом | F23: IfcFooting
A24: ЭЛ 10 10 40 03 | B24: Земляные сооружения, фундаменты | C24: Фундаменты | D24: Фундаментный блок | E24: Фундаментный блок пустотный | F24: IfcFooting
A25: ЭЛ 10 10 45 | B25: Земляные сооружения, фундаменты | C25: Фундаменты | D25: Подливка фундамента | F25: IfcSlab
A26: ЭЛ 10 10 50 | B26: Земляные сооружения, фундаменты | C26: Фундаменты | D26: Подколонник | F26: IfcFooting
A27: ЭЛ 10 10 65 | B27: Земляные сооружения, фундаменты | C27: Фундаменты | D27: Бетонная подготовка | F27: IfcSlab
A28: ЭЛ 10 10 70 | B28: Земляные сооружения, фундаменты | C28: Фундаменты | D28: Кесонный фундамент | F28: IfcFooting
A29: ЭЛ 10 20 | B29: Земляные сооружения, фундаменты | C29: Подпорные стены
A30: ЭЛ 10 20 10 | B30: Земляные сооружения, фундаменты | C30: Подпорные стены | D30: Несущая стена в грунте | F30: IfcWall
A31: ЭЛ 10 20 20 | B31: Земляные сооружения, фундаменты | C31: Подпорные стены | D31: Шпунт Ларсена | F31: IfcPile
A32: ЭЛ 10 20 30 | B32: Земляные сооружения, фундаменты | C32: Подпорные стены | D32: Шпунт | F32: IfcPile
A33: ЭЛ 10 20 40 | B33: Земляные сооружения, фундаменты | C33: Подпорные стены | D33: Подпорная стена | F33: IfcWall
A34: ЭЛ 10 20 50 | B34: Земляные сооружения, фундаменты | C34: Подпорные стены | D34: Габион | F34: IfcWall
A35: ЭЛ 10 25 | B35: Земляные сооружения, фундаменты | C35: Основание
A36: ЭЛ 10 25 10 | B36: Земляные сооружения, фундаменты | C36: Основание | D36: Уплотненный трамбованием грунт | F36: IfcReinforcedSoil
A37: ЭЛ 10 25 20 | B37: Земляные сооружения, фундаменты | C37: Основание | D37: Укрепленный инъецированием грунт | F37: IfcReinforcedSoil
A38: ЭЛ 10 25 30 | B38: Земляные сооружения, фундаменты | C38: Основание | D38: Грунтовая подушка | F38: IfcReinforcedSoil
A39: ЭЛ 10 25 40 | B39: Земляные сооружения, фундаменты | C39: Основание | D39: Уплотненный укаткой грунт | F39: IfcReinforcedSoil
A40: ЭЛ 10 25 50 | B40: Земляные сооружения, фундаменты | C40: Основание | D40: Предварительно обжатый грунт | F40: IfcReinforcedSoil
...

Sheet МССК-8 (Мат.)
A1: КЛАССИФИКАТОРЫ ДЛЯ ИНФОРМАЦИОННОГО МОДЕЛИРОВАНИЯ. Часть 8. КЛАССИФИКАТОР «СТРОИТЕЛЬНЫЕ ИЗДЕЛИЯ И МАТЕРИАЛЫ». Москва 2024
A2: Код | B2: Категория | C2: Тип или назначение | D2: Группа по материалу или назначению | E2: Подгруппа по материалу или назначению | F2: Строительное изделие, материл или группа материалов | G2: Код ОКПД2
A3: СТ 00 | B3: Конструкционные материалы
A4: СТ 00 10 | B4: Конструкционные материалы | C4: Бетон
A5: СТ 00 10 01 | B5: Конструкционные материалы | C5: Бетон | D5: Бетон сборный
A6: СТ 00 10 02 | B6: Конструкционные материалы | C6: Бетон | D6: Бетон монолитный
A7: СТ 00 15 | B7: Конструкционные материалы | C7: Железобетон
A8: СТ 00 15 01 | B8: Конструкционные материалы | C8: Железобетон | D8: Железобетон сборный
A9: СТ 00 15 02 | B9: Конструкционные материалы | C9: Железобетон | D9: Железобетон монолитный
A10: СТ 00 20 | B10: Конструкционные материалы | C10: Дерево
A11: СТ 00 30 | B11: Конструкционные материалы | C11: Камень
A12: СТ 00 40 | B12: Конструкционные материалы | C12: Кирпич
A13: СТ 00 50 | B13: Конструкционные материалы | C13: Композит
A14: СТ 00 60 | B14: Конструкционные материалы | C14: Сталь
A15: СТ 00 70 | B15: Конструкционные материалы | C15: Стекло
A16: СТ 00 80 | B16: Конструкционные материалы | C16: Пластмасса
A17: СТ 00 90 | B17: Конструкционные материалы | C17: Чугун
A18: СТ 10 | B18: Строительные материалы
A19: СТ 10 01 | B19: Строительные материалы | C19: Массив дерева
A20: СТ 10 01 10 | B20: Строительные материалы | C20: Массив дерева | D20: Береза
A21: СТ 10 01 15 | B21: Строительные материалы | C21: Массив дерева | D21: Бук
A22: СТ 10 01 20 | B22: Строительные материалы | C22: Массив дерева | D22: Вишня
A23: СТ 10 01 25 | B23: Строительные материалы | C23: Массив дерева | D23: Дуб
A24: СТ 10 01 30 | B24: Строительные материалы | C24: Массив дерева | D24: Ель
A25: СТ 10 01 35 | B25: Строительные материалы | C25: Массив дерева | D25: Кедр
A26: СТ 10 01 40 | B26: Строительные материалы | C26: Массив дерева | D26: Клен
A27: СТ 10 01 45 | B27: Строительные материалы | C27: Массив дерева | D27: Лиственница
A28: СТ 10 01 50 | B28: Строительные материалы | C28: Массив дерева | D28: Мербау
A29: СТ 10 01 55 | B29: Строительные материалы | C29: Массив дерева | D29: Орех
A30: СТ 10 01 60 | B30: Строительные материалы | C30: Массив дерева | D30: Сосна
A31: СТ 10 01 65 | B31: Строительные материалы | C31: Массив дерева | D31: Ясень
A32: СТ 10 02 | B32: Строительные материалы | C32: Металл
A33: СТ 10 02 10 | B33: Строительные материалы | C33: Металл | D33: Черные металлы, сталь, чугун
A34: СТ 10 02 10 10 | B34: Строительные материалы | C34: Металл | D34: Черные металлы, сталь, чугун | E34: Чугун
A35: СТ 10 02 10 10 10 | B35: Строительные материалы | C35: Металл | D35: Черные металлы, сталь, чугун | E35: Чугун | F35: Высокопрочный чугун
A36: СТ 10 02 10 10 20 | B36: Строительные материалы | C36: Металл | D36: Черные металлы, сталь, чугун | E36: Чугун | F36: Ковкий чугун
A37: СТ 10 02 10 10 30 | B37: Строительные материалы | C37: Металл | D37: Черные металлы, сталь, чугун | E37: Чугун | F37: Серый чугун
A38: СТ 10 02 10 20 | B38: Строительные материалы | C38: Металл | D38: Черные металлы, сталь, чугун | E38: Сталь углеродистая
A39: СТ 10 02 10 20 10 | B39: Строительные материалы | C39: Металл | D39: Черные металлы, сталь, чугун | E39: Сталь углеродистая | F39: Сталь высокоуглеродистая
A40: СТ 10 02 10 20 20 | B40: Строительные материалы | C40: Металл | D40: Черные металлы, сталь, чугун | E40: Сталь углеродистая | F40: Сталь низкоуглеродистая
...
